Workbook

Sheet 清单封面
B1: CSP卓越维保有限公司 | L1: 表内红色字体处为封面需输入内容，其他各清单对应与封面自动连接，连接如下表：
B2: 制 作 清 单 | L2: 工程名称： | M2: 自动连接
L3: 工程编号： | M3: 自动连接
L4: 油漆分类做法： | M4: （手动输入）
B7: 工 程 名 称： | C7: 第三选矿区C栋宿舍
B8: 工 程 编 号： | C8: HA24575
B10: 清单组成： | C10: 序号 | D10: 分类 | E10: 清单名称 | F10: 备注 | H10: 重量kg | I10: 各清单工程编号代码 | J10: 是否有
C11: 1 | D11: 总构件清单 | E11: 结算清单 | F11: (总构件清单) | H11: ='结算清单(总构件清单)'!I401 -> 756132.6 | I11: =C8 -> HA24575 | J11: √
C12: 2 | D12: 构件清单（分类） | E12: 构件清单-1 | F12: (普通构件) | H12: ='构件清单-1（普通构件）'!I327 -> 740279.4 | I12: =C8 -> HA24575 | J12: √
C13: 3 | E13: 构件清单-2 | F13: (外购材料构件) | H13: ='构件清单-2（外购材料构件）'!I31 -> 0 | I13: =C8&"W" -> HA24575W | J13: ×
C14: 4 | E14: 构件清单-3 | F14: (箱型构件) | H14: ='构件清单-3（箱型构件）'!I42 -> 0 | I14: =C8&"X" -> HA24575X | J14: ×
C15: 5 | E15: 构件清单-4 | F15: (钢梯&栏杆) | H15: ='构件清单-4（钢梯&栏杆）'!I81 -> 15853.2 | I15: =C8&"T" -> HA24575T | J15: √
C16: 6 | E16: 构件清单-5 | F16: (檩条&拉条) | H16: ='构件清单-5（檩条&拉条）'!I42 -> 0 | I16: =C8 -> HA24575 | J16: ×
C17: 7 | D17: 小件下料 | E17: 零件清单 | F17: (仅小板件) | H17: =零件清单!I214 -> 95700.4 | I17: =C8 -> HA24575 | J17: √
C18: 8 | D18: 型钢组立 | E18: 组立清单 | F18: (仅型钢翼、腹板) | H18: =组立清单!I104 -> 642007.23 | I18: =C8 -> HA24575 | J18: √
C19: 9 | D19: 大板下料 | E19: 排版清单 | F19: (仅型钢翼、腹板，未加余量) | H19: =排板清单!H122 -> 702538.23 | I19: =C8 -> HA24575 | J19: √
L20: 其他油漆备用文字
B21: 油漆分类做法： | C21: 主结构 | D21: 1.[底漆]:规格:环氧富锌，颜色:浅灰色，厚度:70u/遍，涂刷遍数:2遍，含锌量不低于80% 2.[面漆]:规格:脂肪族聚氨酯，颜色: 中灰色，厚度:70u/遍，涂刷遍数:2遍. 干膜油漆总厚度≥125μ。 | L21: 油漆标准1（环氧+聚氨酯）： | M21: 1.[底漆]：环氧富锌, 颜色：浅灰色，涂刷2遍(35μ/遍)，厚度共计：70μm； 2.[中漆]：环氧云铁, 颜色：浅灰色，涂刷3遍(35μ/遍)，厚度共计：110μm； 3.[面漆]：脂肪族聚氨酯，颜色：中灰色(色号B02)/海蓝色(色号PB05)/淡黄色(色号Y06)，涂刷3遍，厚度共计：100μm； 4.干膜总厚度≥280μm。 | AA21: 淡黄色(色号Y06)常用于栏杆
C22: 钢梯、栏杆 | D22: 1.铁红醇酸底漆75μ（两遍）醇酸2.白色醇酸面漆两遍75μ | L22: 油漆标准2（环氧+氯化橡胶）： | M22: 1.[底漆]：环氧富锌，颜色：浅灰色，涂刷1遍(45μ/遍),厚度共计：45μm ； 2.[中漆]：环氧云铁，颜色：浅灰色，涂刷2遍(45μ/遍),厚度共计：90μm； 3.[面漆]：氯化橡胶，颜色：灰色(色号RAL7037)，涂刷2遍(45μ/遍),厚度共计：90μm； 4.干膜油漆总厚度≥240μm。
C23: 其他特殊构件 | D23: 【材料问题】 C150*75*6.5材料为甲供，用于平台梁和钢梯，其中钢梯所用。C150*75*6.5的材料重量已体现在清单的备注栏。 | L23: 油漆标准3（醇酸）： | M23: 1.[底漆]：醇酸，颜色：红丹，涂刷2遍(35μ/遍),厚度共计：70μm； 2.[面漆]：醇酸，颜色：中灰/中黄色/白色，涂刷2遍(35μ/遍),厚度共计：70μm； 3.干膜油漆总厚度≥125μm。 | AA23: 中黄色/白色常用于栏杆
B25: 编 制 人： | G25: 组立、排版人：
B26: 校 对 人：
B27: 审 核 人：
B28: 时 间： | C28: 45697
A30: 钢结构技术科

Sheet 备料清单
A1: =#REF! -> #REF!
A2: 备 料 清 单
A3: ='结算清单(总构件清单)'!A4 -> 工 程 名 称：
A4: ='结算清单(总构件清单)'!A5 -> 工 程 编 号： | F4: ='结算清单(总构件清单)'!F5 -> 0
A5: ='结算清单(总构件清单)'!#REF! -> #REF! | F5: ='结算清单(总构件清单)'!#REF! -> #REF!
A6: 材料名称 | B6: 材料规格 | C6: 单位 | D6: 数量 | E6: 材质 | F6: 库存 | G6: 供货厂家 | H6: 金额合计 | I6: 备注/长度（M）
A7: 栓钉 | B7: D19X110 | C7: 颗 | D7: =SUMIFS('结算清单(总构件清单)'!F:F,'结算清单(总构件清单)'!C:C,A7) -> 0 | E7: 配磁环

Sheet 结算清单(总构件清单)
A1: CSP卓越维保有限公司
A2: =清单封面!E11 -> 结算清单 | H2: =清单封面!F11 -> (总构件清单)
A4: =清单封面!B7 -> 工 程 名 称： | C4: =清单封面!C7 -> 第三选矿区C栋宿舍
A5: =清单封面!B8 -> 工 程 编 号： | C5: =清单封面!I11 -> HA24575
A6: 序号 | B6: 构件名称 | C6: 构件编号 | D6: 规格 | E6: 长度mm | F6: 材质 | G6: 数量 | H6: 单重Kg | I6: 总重Kg | J6: 单件面积㎡ | K6: 总面积㎡ | L6: 备注
A7: 1 | B7: 钢次梁 | C7: GCL1-1 | D7: HI650-14-20*300 | E7: 7016 | F7: Q355B | G7: 12 | H7: 1164.7 | I7: 13976.3 | J7: 18.68 | K7: 224.17
A8: 2 | B8: 钢次梁 | C8: GCL1-2 | D8: HI650-14-20*300 | E8: 7018 | F8: Q355B | G8: 3 | H8: 1164.8 | I8: 3494.4 | J8: 18.68 | K8: 56.05
A9: 3 | B9: 钢次梁 | C9: GCL1-3 | D9: HI650-14-20*300 | E9: 7018 | F9: Q355B | G9: 2 | H9: 1164.8 | I9: 2329.6 | J9: 18.68 | K9: 37.37
A10: 4 | B10: 钢次梁 | C10: GCL1-4 | D10: HI650-14-20*300 | E10: 6866 | F10: Q355B | G10: 16 | H10: 1137.6 | I10: 18201.8 | J10: 18.25 | K10: 292
A11: 5 | B11: 钢次梁 | C11: GCL1-5 | D11: HI650-14-20*300 | E11: 2746 | F11: Q355B | G11: 1 | H11: 444.9 | I11: 444.9 | J11: 7.1 | K11: 7.1
A12: 6 | B12: 钢次梁 | C12: GCL1-6 | D12: HI650-14-20*300 | E12: 5805.5 | F12: Q355B | G12: 1 | H12: 965.4 | I12: 965.4 | J12: 15.38 | K12: 15.38
A13: 7 | B13: 钢次梁 | C13: GCL1-7 | D13: HI650-14-20*300 | E13: 5956 | F13: Q355B | G13: 11 | H13: 989.7 | I13: 10886.4 | J13: 15.75 | K13: 173.27
A14: 8 | B14: 钢次梁 | C14: GCL1-8 | D14: HI650-14-20*300 | E14: 5801 | F14: Q355B | G14: 1 | H14: 964.7 | I14: 964.7 | J14: 15.37 | K14: 15.37
A15: 9 | B15: 钢次梁 | C15: GCL1-9 | D15: HI650-14-20*300 | E15: 5801 | F15: Q355B | G15: 1 | H15: 964.7 | I15: 964.7 | J15: 15.37 | K15: 15.37
A16: 10 | B16: 钢次梁 | C16: GCL1-10 | D16: HI650-14-20*300 | E16: 5956 | F16: Q355B | G16: 3 | H16: 989.7 | I16: 2969 | J16: 15.75 | K16: 47.25
A17: 11 | B17: 钢次梁 | C17: GCL1-11 | D17: HI300-8-10*200 | E17: 2679.5 | F17: Q355B | G17: 10 | H17: 131.3 | I17: 1312.5 | J17: 3.72 | K17: 37.21
A18: 12 | B18: 钢次梁 | C18: GCL1-12 | D18: HI300-8-10*200 | E18: 2575 | F18: Q355B | G18: 12 | H18: 126.1 | I18: 1513.6 | J18: 3.58 | K18: 42.92
... A291: 285 | B291: 平台板 | C291: PTB-21 | D291: 平台板 | E291: 2840 | F291: 花纹板 | G291: 1 | H291: 340.2 | I291: 340.2 | J291: 16.47 | K291: 16.47
A292: 286 | B292: 平台梁 | C292: PTL1-1 | D292: C150*75*6.5 | E292: 1480 | F292: Q355B | G292: 24 | H292: 21.7 | I292: 520.2 | J292: 0.87 | K292: 20.94 | L292: 甲供材料
A293: 287 | B293: 平台梁 | C293: PTL1-2 | D293: C150*75*6.5 | E293: 2640 | F293: Q355B | G293: 28 | H293: 38.7 | I293: 1082.5 | J293: 1.55 | K293: 43.5
A294: 288 | B294: 平台梁 | C294: PTL1-3 | D294: C150*75*6.5 | E294: 940 | F294: Q355B | G294: 4 | H294: 13.8 | I294: 55.1 | J294: 0.56 | K294: 2.22
A295: 289 | B295: 平台梁 | C295: PTL1-4 | D295: C150*75*6.5 | E295: 1631 | F295: Q355B | G295: 12 | H295: 23.9 | I295: 286.6 | J295: 0.96 | K295: 11.53
A296: 290 | B296: 平台梁 | C296: PTL1-5 | D296: C150*75*6.5 | E296: 2251 | F296: Q355B | G296: 14 | H296: 33 | I296: 461.5 | J296: 1.33 | K296: 18.55
A297: 291 | B297: 平台梁 | C297: PTL1-6 | D297: C150*75*6.5 | E297: 1091 | F297: Q355B | G297: 2 | H297: 16 | I297: 32 | J297: 0.64 | K297: 1.29
A298: 292 | B298: 平台梁 | C298: PTL1-7 | D298: C150*75*6.5 | E298: 1325 | F298: Q355B | G298: 2 | H298: 19.4 | I298: 38.8 | J298: 0.78 | K298: 1.56
A299: 293 | B299: 平台梁 | C299: PTL1-8 | D299: C150*75*6.5 | E299: 898 | F299: Q355B | G299: 1 | H299: 13.2 | I299: 13.2 | J299: 0.53 | K299: 0.53
A300: 294 | B300: 平台梁 | C300: PTL1-9 | D300: C150*75*6.5 | E300: 1515 | F300: Q355B | G300: 16 | H300: 22.2 | I300: 355 | J300: 0.89 | K300: 14.29
A301: 295 | B301: 平台梁 | C301: PTL1-10 | D301: C150*75*6.5 | E301: 2667 | F301: Q355B | G301: 4 | H301: 39.1 | I301: 156.2 | J301: 1.57 | K301: 6.28
A302: 296 | B302: 平台梁 | C302: PTL1-11 | D302: C150*75*6.5 | E302: 2518.5 | F302: Q355B | G302: 4 | H302: 36.9 | I302: 147.5 | J302: 1.48 | K302: 5.93
A303: 297 | B303: 平台梁 | C303: PTL1-12 | D303: C150*75*6.5 | E303: 1245 | F303: Q355B | G303: 4 | H303: 18.2 | I303: 72.9 | J303: 0.73 | K303: 2.94
A304: 298 | B304: 平台梁 | C304: PTL1-13 | D304: C150*75*6.5 | E304: 1110 | F304: Q355B | G304: 4 | H304: 16.3 | I304: 65 | J304: 0.66 | K304: 2.62
... A315: 309 | B315: 平台梁 | C315: PTL1-24 | D315: C150*75*6.5 | E315: 2785.5 | F315: Q355B | G315: 1 | H315: 39.9 | I315: 39.9 | J315: 1.61 | K315: 1.61
A316: 310 | B316: 散发件 | C316: SF1 | D316: PL20*70 | E316: 70 | F316: Q355B | G316: 576 | H316: 0.8 | I316: 443.1 | J316: 0.02 | K316: 8.87 | L316: 现场件
A317: 311 | B317: 散发件 | C317: SF2 | D317: PL12*90 | E317: 385 | F317: Q355B | G317: 112 | H317: 3.3 | I317: 365.6 | J317: 0.08 | K317: 9.04
A318: 312 | B318: 散发件 | C318: SF3 | D318: PL16*346 | E318: 885 | F318: Q355B | G318: 24 | H318: 38.5 | I318: 923 | J318: 0.65 | K318: 15.64
A319: 313 | B319: 散发件 | C319: SF4 | D319: PL16*346 | E319: 885 | F319: Q355B | G319: 10 | H319: 38.5 | I319: 384.6 | J319: 0.65 | K319: 6.52
A320: 314 | B320: 散发件 | C320: SF5 | D320: PL6*30 | E320: 255 | F320: Q355B | G320: 390 | H320: 0.4 | I320: 140.5 | J320: 0.02 | K320: 7.3
A321: 315 | B321: 散发件 | C321: SF6 | D321: PL6*30 | E321: 290 | F321: Q355B | G321: 130 | H321: 0.4 | I321: 53.3 | J321: 0.02 | K321: 2.76
A322: 316 | B322: 散发件 | C322: SF7 | D322: PL6*30 | E322: 238 | F322: Q355B | G322: 72 | H322: 0.3 | I322: 24.2 | J322: 0.02 | K322: 1.26
A323: 317 | B323: 散发件 | C323: SF8 | D323: PL6*30 | E323: 270 | F323: Q355B | G323: 168 | H323: 0.4 | I323: 64.1 | J323: 0.02 | K323: 3.33
...

Sheet 构件清单-1（普通构件）
A1: CSP卓越维保有限公司
A2: =清单封面!E12 -> 构件清单-1 | H2: =清单封面!F12 -> (普通构件)
A4: =清单封面!B7 -> 工 程 名 称： | C4: =清单封面!C7 -> 第三选矿区C栋宿舍
A5: =清单封面!B8 -> 工 程 编 号： | C5: =清单封面!I12 -> HA24575
A6: 序号 | B6: 构件名称 | C6: 构件编号 | D6: 规格 | E6: 长度mm | F6: 材质 | G6: 数量 | H6: 单重Kg | I6: 总重Kg | J6: 单件面积㎡ | K6: 总面积㎡ | L6: 备注
A7: 1 | B7: 钢次梁 | C7: GCL1-1 | D7: HI650-14-20*300 | E7: 7016 | F7: Q355B | G7: 12 | H7: 1164.7 | I7: 13976.3 | J7: 18.68 | K7: 224.17
A8: 2 | B8: 钢次梁 | C8: GCL1-2 | D8: HI650-14-20*300 | E8: 7018 | F8: Q355B | G8: 3 | H8: 1164.8 | I8: 3494.4 | J8: 18.68 | K8: 56.05
A9: 3 | B9: 钢次梁 | C9: GCL1-3 | D9: HI650-14-20*300 | E9: 7018 | F9: Q355B | G9: 2 | H9: 1164.8 | I9: 2329.6 | J9: 18.68 | K9: 37.37
A10: 4 | B10: 钢次梁 | C10: GCL1-4 | D10: HI650-14-20*300 | E10: 6866 | F10: Q355B | G10: 16 | H10: 1137.6 | I10: 18201.8 | J10: 18.25 | K10: 292
A11: 5 | B11: 钢次梁 | C11: GCL1-5 | D11: HI650-14-20*300 | E11: 2746 | F11: Q355B | G11: 1 | H11: 444.9 | I11: 444.9 | J11: 7.1 | K11: 7.1
A12: 6 | B12: 钢次梁 | C12: GCL1-6 | D12: HI650-14-20*300 | E12: 5805.5 | F12: Q355B | G12: 1 | H12: 965.4 | I12: 965.4 | J12: 15.38 | K12: 15.38
A13: 7 | B13: 钢次梁 | C13: GCL1-7 | D13: HI650-14-20*300 | E13: 5956 | F13: Q355B | G13: 11 | H13: 989.7 | I13: 10886.4 | J13: 15.75 | K13: 173.27
A14: 8 | B14: 钢次梁 | C14: GCL1-8 | D14: HI650-14-20*300 | E14: 5801 | F14: Q355B | G14: 1 | H14: 964.7 | I14: 964.7 | J14: 15.37 | K14: 15.37
A15: 9 | B15: 钢次梁 | C15: GCL1-9 | D15: HI650-14-20*300 | E15: 5801 | F15: Q355B | G15: 1 | H15: 964.7 | I15: 964.7 | J15: 15.37 | K15: 15.37
A16: 10 | B16: 钢次梁 | C16: GCL1-10 | D16: HI650-14-20*300 | E16: 5956 | F16: Q355B | G16: 3 | H16: 989.7 | I16: 2969 | J16: 15.75 | K16: 47.25
A17: 11 | B17: 钢次梁 | C17: GCL1-11 | D17: HI300-8-10*200 | E17: 2679.5 | F17: Q355B | G17: 10 | H17: 131.3 | I17: 1312.5 | J17: 3.72 | K17: 37.21
A18: 12 | B18: 钢次梁 | C18: GCL1-12 | D18: HI300-8-10*200 | E18: 2575 | F18: Q355B | G18: 12 | H18: 126.1 | I18: 1513.6 | J18: 3.58 | K18: 42.92
... A239: 233 | B239: 平台板 | C239: PTB-21 | D239: 平台板 | E239: 2840 | F239: 花纹板 | G239: 1 | H239: 340.2 | I239: 340.2 | J239: 16.47 | K239: 16.47
A240: 234 | B240: 散发件 | C240: SF1 | D240: PL20*70 | E240: 70 | F240: Q355B | G240: 576 | H240: 0.8 | I240: 443.1 | J240: 0.02 | K240: 8.87 | L240: 现场件
A241: 235 | B241: 散发件 | C241: SF2 | D241: PL12*90 | E241: 385 | F241: Q355B | G241: 112 | H241: 3.3 | I241: 365.6 | J241: 0.08 | K241: 9.04
A242: 236 | B242: 散发件 | C242: SF3 | D242: PL16*346 | E242: 885 | F242: Q355B | G242: 24 | H242: 38.5 | I242: 923 | J242: 0.65 | K242: 15.64
A243: 237 | B243: 散发件 | C243: SF4 | D243: PL16*346 | E243: 885 | F243: Q355B | G243: 10 | H243: 38.5 | I243: 384.6 | J243: 0.65 | K243: 6.52
A244: 238 | B244: 散发件 | C244: SF5 | D244: PL6*30 | E244: 255 | F244: Q355B | G244: 390 | H244: 0.4 | I244: 140.5 | J244: 0.02 | K244: 7.3
A245: 239 | B245: 散发件 | C245: SF6 | D245: PL6*30 | E245: 290 | F245: Q355B | G245: 130 | H245: 0.4 | I245: 53.3 | J245: 0.02 | K245: 2.76
A246: 240 | B246: 散发件 | C246: SF7 | D246: PL6*30 | E246: 238 | F246: Q355B | G246: 72 | H246: 0.3 | I246: 24.2 | J246: 0.02 | K246: 1.26
A247: 241 | B247: 散发件 | C247: SF8 | D247: PL6*30 | E247: 270 | F247: Q355B | G247: 168 | H247: 0.4 | I247: 64.1 | J247: 0.02 | K247: 3.33
A248: 242 | B248: 散发件 | C248: SF9 | D248: PL16*90 | E248: 665 | F248: Q355B | G248: 136 | H248: 7.5 | I248: 1022.3 | J248: 0.14 | K248: 19.56
A249: 243 | B249: 散发件 | C249: SF10 | D249: PL6*30 | E249: 305 | F249: Q355B | G249: 96 | H249: 0.4 | I249: 41.4 | J249: 0.02 | K249: 2.14
A250: 244 | B250: 散发件 | C250: SF11 | D250: PL6*30 | E250: 220 | F250: Q355B | G250: 312 | H250: 0.3 | I250: 97 | J250: 0.02 | K250: 5.05
A251: 245 | B251: 散发件 | C251: SF12 | D251: PL6*30 | E251: 320 | F251: Q355B | G251: 242 | H251: 0.5 | I251: 109.4 | J251: 0.02 | K251: 5.66
A252: 246 | B252: 散发件 | C252: SF13 | D252: PL6*30 | E252: 390 | F252: Q355B | G252: 128 | H252: 0.6 | I252: 70.5 | J252: 0.03 | K252: 3.64
... A302: 296 | B302: 梯柱 | C302: TZ-22 | D302: HI250-10-14*250 | E302: 20605 | F302: Q355B | G302: 2 | H302: 1699.2 | I302: 3398.4 | J302: 35.17 | K302: 70.33
A303: 297 | B303: 平台梁 | C303: PTL1-1 | D303: C150*75*6.5 | E303: 1480 | F303: Q355B | G303: 24 | H303: 21.7 | I303: 520.2 | J303: 0.87 | K303: 20.94 | L303: 甲供材料
A304: 298 | B304: 平台梁 | C304: PTL1-2 | D304: C150*75*6.5 | E304: 2640 | F304: Q355B | G304: 28 | H304: 38.7 | I304: 1082.5 | J304: 1.55 | K304: 43.5
A305: 299 | B305: 平台梁 | C305: PTL1-3 | D305: C150*75*6.5 | E305: 940 | F305: Q355B | G305: 4 | H305: 13.8 | I305: 55.1 | J305: 0.56 | K305: 2.22
A306: 300 | B306: 平台梁 | C306: PTL1-4 | D306: C150*75*6.5 | E306: 1631 | F306: Q355B | G306: 12 | H306: 23.9 | I306: 286.6 | J306: 0.96 | K306: 11.53
A307: 301 | B307: 平台梁 | C307: PTL1-5 | D307: C150*75*6.5 | E307: 2251 | F307: Q355B | G307: 14 | H307: 33 | I307: 461.5 | J307: 1.33 | K307: 18.55
A308: 302 | B308: 平台梁 | C308: PTL1-6 | D308: C150*75*6.5 | E308: 1091 | F308: Q355B | G308: 2 | H308: 16 | I308: 32 | J308: 0.64 | K308: 1.29
A309: 303 | B309: 平台梁 | C309: PTL1-7 | D309: C150*75*6.5 | E309: 1325 | F309: Q355B | G309: 2 | H309: 19.4 | I309: 38.8 | J309: 0.78 | K309: 1.56
A310: 304 | B310: 平台梁 | C310: PTL1-8 | D310: C150*75*6.5 | E310: 898 | F310: Q355B | G310: 1 | H310: 13.2 | I310: 13.2 | J310: 0.53 | K310: 0.53
...

Sheet 构件清单-2（外购材料构件）
A1: CSP卓越维保有限公司
A2: =清单封面!E13 -> 构件清单-2 | H2: =清单封面!F13 -> (外购材料构件)
A4: =清单封面!B7 -> 工 程 名 称： | C4: =清单封面!C7 -> 第三选矿区C栋宿舍
A5: =清单封面!B8 -> 工 程 编 号： | C5: =清单封面!I13 -> HA24575W
A6: 序号 | B6: 构件名称 | C6: 构件编号 | D6: 规格 | E6: 长度mm | F6: 材质 | G6: 数量 | H6: 单重Kg | I6: 总重Kg | J6: 单件面积㎡ | K6: 总面积㎡ | L6: 备注
A7: 1
A8: 2
A9: 3
A10: 4
A11: 5
A12: 6
A13: 7
A14: 8
A15: 9
A16: 10
A17: 11
A18: 12
... A23: 17
A24: 18 | U24: S
A25: 19
A26: 20
A27: 21
A28: 22
A29: 23
A30: 24
F31: 合计： | G31: =SUM(G7:G30) -> 0 | I31: =SUM(I7:I30) -> 0 | K31: =SUM(K7:K30) -> 0 | M31: 此行严禁删除！

Sheet 构件清单-3（箱型构件）
A1: CSP卓越维保有限公司
A2: =清单封面!E14 -> 构件清单-3 | H2: =清单封面!F14 -> (箱型构件)
A4: =清单封面!B7 -> 工 程 名 称： | C4: =清单封面!C7 -> 第三选矿区C栋宿舍
A5: =清单封面!B8 -> 工 程 编 号： | C5: =清单封面!I14 -> HA24575X
A6: 序号 | B6: 构件名称 | C6: 构件编号 | D6: 规格 | E6: 长度mm | F6: 材质 | G6: 数量 | H6: 单重Kg | I6: 总重Kg | J6: 单件面积㎡ | K6: 总面积㎡ | L6: 备注
A7: 1
A8: 2
A9: 3
A10: 4
A11: 5
A12: 6
A13: 7
A14: 8
A15: 9
A16: 10
A17: 11
A18: 12
... A41: 35
F42: 合计： | G42: =SUM(G7:G41) -> 0 | I42: =SUM(I7:I41) -> 0 | K42: =SUM(K7:K41) -> 0 | M42: 此行严禁删除！

Sheet 构件清单-4（钢梯&栏杆）
A1: CSP卓越维保有限公司
A2: =清单封面!E15 -> 构件清单-4 | H2: =清单封面!F15 -> (钢梯&栏杆)
A4: =清单封面!B7 -> 工 程 名 称： | C4: =清单封面!C7 -> 第三选矿区C栋宿舍
A5: =清单封面!B8 -> 工 程 编 号： | C5: =清单封面!I15 -> HA24575T
A6: 序号 | B6: 构件名称 | C6: 构件编号 | D6: 规格 | E6: 长度mm | F6: 材质 | G6: 数量 | H6: 单重Kg | I6: 总重Kg | J6: 单件面积㎡ | K6: 总面积㎡ | L6: 备注
A7: 1 | B7: 栏杆 | C7: LG-1 | D7: PD47*3 | E7: 940 | F7: Q235B | G7: 1 | H7: 17.2 | I7: 17.2 | J7: 0.87 | K7: 0.87
A8: 2 | B8: 栏杆 | C8: LG-2 | D8: PD47*3 | E8: 4148.8 | F8: Q235B | G8: 1 | H8: 47.3 | I8: 47.3 | J8: 2.49 | K8: 2.49
A9: 3 | B9: 栏杆 | C9: LG-3 | D9: PD47*3 | E9: 4148.8 | F9: Q235B | G9: 1 | H9: 47.3 | I9: 47.3 | J9: 2.49 | K9: 2.49
A10: 4 | B10: 栏杆 | C10: LG-4 | D10: PD47*3 | E10: 3969.7 | F10: Q235B | G10: 1 | H10: 45.7 | I10: 45.7 | J10: 2.4 | K10: 2.4
A11: 5 | B11: 栏杆 | C11: LG-5 | D11: PD47*3 | E11: 3969.7 | F11: Q235B | G11: 1 | H11: 45.7 | I11: 45.7 | J11: 2.4 | K11: 2.4
A12: 6 | B12: 栏杆 | C12: LG-6 | D12: PD47*3 | E12: 3775.2 | F12: Q235B | G12: 1 | H12: 43.7 | I12: 43.7 | J12: 2.29 | K12: 2.29
A13: 7 | B13: 栏杆 | C13: LG-7 | D13: PD47*3 | E13: 3775.2 | F13: Q235B | G13: 1 | H13: 43.7 | I13: 43.7 | J13: 2.29 | K13: 2.29
A14: 8 | B14: 栏杆 | C14: LG-8 | D14: PD47*3 | E14: 3186 | F14: Q235B | G14: 1 | H14: 35.4 | I14: 35.4 | J14: 1.85 | K14: 1.85
A15: 9 | B15: 栏杆 | C15: LG-9 | D15: PD47*3 | E15: 3186 | F15: Q235B | G15: 1 | H15: 35.4 | I15: 35.4 | J15: 1.85 | K15: 1.85
A16: 10 | B16: 栏杆 | C16: LG-10 | D16: PD47*3 | E16: 3120.7 | F16: Q235B | G16: 1 | H16: 35.1 | I16: 35.1 | J16: 1.83 | K16: 1.83
A17: 11 | B17: 栏杆 | C17: LG-11 | D17: PD47*3 | E17: 3120.7 | F17: Q235B | G17: 1 | H17: 35.1 | I17: 35.1 | J17: 1.83 | K17: 1.83
A18: 12 | B18: 栏杆 | C18: LG-12 | D18: PD47*3 | E18: 3124.3 | F18: Q235B | G18: 2 | H18: 35.1 | I18: 70.1 | J18: 1.84 | K18: 3.67
... A58: 52 | B58: 栏杆 | C58: LG-52 | D58: PD47*3 | E58: 2447 | F58: Q235B | G58: 26 | H58: 20.8 | I58: 539.7 | J58: 1.09 | K58: 28.28
A59: 53 | B59: 钢梯 | C59: ST-1 | D59: C150*75*6.5 | E59: 2835.9 | F59: Q355B | G59: 1 | H59: 206.6 | I59: 206.6 | J59: 9.75 | K59: 9.75 | L59: 77.52
A60: 54 | B60: 钢梯 | C60: ST-2 | D60: C150*75*6.5 | E60: 2835.9 | F60: Q355B | G60: 1 | H60: 206.6 | I60: 206.6 | J60: 9.75 | K60: 9.75 | L60: 77.52
A61: 55 | B61: 钢梯 | C61: ST-3 | D61: C150*75*6.5 | E61: 2895.9 | F61: Q355B | G61: 2 | H61: 223.1 | I61: 446.3 | J61: 10.61 | K61: 21.22 | L61: 164.4
A62: 56 | B62: 钢梯 | C62: ST-4 | D62: C150*75*6.5 | E62: 2845.7 | F62: Q355B | G62: 2 | H62: 220.5 | I62: 441.1 | J62: 10.49 | K62: 20.98 | L62: 160.88
A63: 57 | B63: 钢梯 | C63: ST-5 | D63: C150*75*6.5 | E63: 2848.5 | F63: Q355B | G63: 2 | H63: 221.9 | I63: 443.8 | J63: 10.56 | K63: 21.12 | L63: 161.92
A64: 58 | B64: 钢梯 | C64: ST-6 | D64: C150*75*6.5 | E64: 3563.2 | F64: Q355B | G64: 2 | H64: 273.9 | I64: 547.8 | J64: 13.01 | K64: 26.02 | L64: 203.28
A65: 59 | B65: 钢梯 | C65: ST-7 | D65: C150*75*6.5 | E65: 3563.2 | F65: Q355B | G65: 2 | H65: 273.3 | I65: 546.7 | J65: 12.98 | K65: 25.97 | L65: 203.28
A66: 60 | B66: 钢梯 | C66: ST-8 | D66: C150*75*6.5 | E66: 2867.8 | F66: Q355B | G66: 8 | H66: 220.7 | I66: 1765.8 | J66: 10.49 | K66: 83.95 | L66: 651.68
A67: 61 | B67: 钢梯 | C67: ST-9 | D67: C150*75*6.5 | E67: 2867.8 | F67: Q355B | G67: 8 | H67: 220.4 | I67: 1762.9 | J67: 10.47 | K67: 83.79 | L67: 651.68
A68: 62 | B68: 钢梯 | C68: ST-10 | D68: C150*75*6.5 | E68: 3911 | F68: Q355B | G68: 1 | H68: 308.2 | I68: 308.2 | J68: 14.57 | K68: 14.57 | L68: 108.16
A69: 63 | B69: 钢梯 | C69: ST-11 | D69: C150*75*6.5 | E69: 3824.8 | F69: Q355B | G69: 1 | H69: 287.3 | I69: 287.3 | J69: 13.48 | K69: 13.48 | L69: 106.98
A70: 64 | B70: 钢梯 | C70: ST-12 | D70: C150*75*6.5 | E70: 3763.7 | F70: Q355B | G70: 1 | H70: 285.4 | I70: 285.4 | J70: 13.4 | K70: 13.4 | L70: 105.3
... A80: 74 | B80: 钢梯 | C80: ST-22 | D80: C150*75*6.5 | E80: 2900.2 | F80: Q355B | G80: 1 | H80: 216.9 | I80: 216.9 | J80: 10.15 | K80: 10.15 | L80: 79.92
F81: 合计： | G81: =SUM(G7:G80) -> 269 | I81: =SUM(I7:I80) -> 15853.2 | K81: =SUM(K7:K80) -> 781.73 | M81: 此行严禁删除！
B83: 备注：钢梯备注栏为甲供材料重量

Sheet 构件清单-5（檩条&拉条）
A1: CSP卓越维保有限公司
A2: =清单封面!E16 -> 构件清单-5 | H2: =清单封面!F16 -> (檩条&拉条)
A4: =清单封面!B7 -> 工 程 名 称： | C4: =清单封面!C7 -> 第三选矿区C栋宿舍
A5: =清单封面!B8 -> 工 程 编 号： | C5: =清单封面!I16 -> HA24575
A6: 序号 | B6: 构件名称 | C6: 构件编号 | D6: 规格 | E6: 长度mm | F6: 材质 | G6: 数量 | H6: 单重Kg | I6: 总重Kg | J6: 单件面积㎡ | K6: 总面积㎡ | L6: 备注
A7: 1
A8: 2
A9: 3
A10: 4
A11: 5
A12: 6
A13: 7
A14: 8
A15: 9
A16: 10
A17: 11
A18: 12
... A40: 33
F42: 合计： | G42: =SUM(G7:G41) -> 0 | I42: =SUM(I7:I41) -> 0 | K42: =SUM(K7:K41) -> 0 | M42: 此行严禁删除！

Sheet 零件清单
A1: CSP卓越维保有限公司
A2: =清单封面!E17 -> 零件清单 | H2: =清单封面!F17 -> (仅小板件)
A4: =清单封面!B7 -> 工 程 名 称： | C4: =清单封面!C7 -> 第三选矿区C栋宿舍
A5: =清单封面!B8 -> 工 程 编 号： | C5: =清单封面!I17 -> HA24575
A6: 序号 | C6: 零件编号 | D6: 规格 | E6: 长度mm | F6: 材质 | G6: 数量 | H6: 单重Kg | I6: 总重Kg | J6: 单件面积㎡ | K6: 总面积㎡ | L6: 备注
A7: 1 | C7: B1 | D7: PL20*602 | E7: 477 | F7: Q355B | G7: 236 | H7: 45 | I7: 10630.8 | J7: 0.51 | K7: 120.32
A8: 2 | C8: B2 | D8: PL20*452 | E8: 477 | F8: Q355B | G8: 88 | H8: 33.8 | I8: 2975.5 | J8: 0.41 | K8: 36.33
A9: 3 | C9: B3 | D9: PL20*446 | E9: 477 | F9: Q355B | G9: 54 | H9: 33.4 | I9: 1801.6 | J9: 0.41 | K9: 21.99
A10: 4 | C10: B4 | D10: PL20*477 | E10: 448.8 | F10: Q355B | G10: 32 | H10: 33.6 | I10: 1075.4 | J10: 0.4 | K10: 12.93
A11: 5 | C11: B5 | D11: PL20*477 | E11: 454.8 | F11: Q355B | G11: 16 | H11: 34.1 | I11: 544.9 | J11: 0.41 | K11: 6.55
A12: 6 | C12: B6 | D12: PL20*477 | E12: 448.8 | F12: Q355B | G12: 16 | H12: 33.6 | I12: 537.7 | J12: 0.4 | K12: 6.46
A13: 7 | C13: B7 | D13: PL20*477 | E13: 454.8 | F13: Q355B | G13: 31 | H13: 34.1 | I13: 1055.8 | J13: 0.41 | K13: 12.7
A14: 8 | C14: B8 | D14: PL20*225 | E14: 452 | F14: Q355B | G14: 208 | H14: 15.9 | I14: 3313.7 | J14: 0.23 | K14: 47.58
A15: 9 | C15: B9 | D15: PL20*35 | E15: 150 | F15: Q355B | G15: 318 | H15: 0.8 | I15: 262.1 | J15: 0.02 | K15: 5.09
A16: 10 | C16: B10 | D16: PL20*35 | E16: 150 | F16: Q355B | G16: 316 | H16: 0.8 | I16: 260.5 | J16: 0.02 | K16: 5.06
A17: 11 | C17: B11 | D17: PL20*240 | E17: 240 | F17: Q355B | G17: 24 | H17: 9 | I17: 217 | J17: 0.13 | K17: 3.23
A18: 12 | C18: B12 | D18: PL20*540 | E18: 740 | F18: Q355B | G18: 8 | H18: 62.7 | I18: 501.9 | J18: 0.85 | K18: 6.8
... A173: 167 | C173: B167 | D173: PL6*400 | E173: 805 | F173: Q355B | G173: 3 | H173: 15.2 | I173: 45.5 | J173: 0.66 | K173: 1.98
A174: 168 | C174: SF1 | D174: PL20*70 | E174: 70 | F174: Q355B | G174: 576 | H174: 0.8 | I174: 443.1 | J174: 0.02 | K174: 8.87 | L174: 直发件
A175: 169 | C175: SF2 | D175: PL12*90 | E175: 385 | F175: Q355B | G175: 112 | H175: 3.3 | I175: 365.6 | J175: 0.08 | K175: 9.04
A176: 170 | C176: SF3 | D176: PL16*346 | E176: 885 | F176: Q355B | G176: 24 | H176: 38.5 | I176: 923 | J176: 0.65 | K176: 15.64
A177: 171 | C177: SF4 | D177: PL16*346 | E177: 885 | F177: Q355B | G177: 10 | H177: 38.5 | I177: 384.6 | J177: 0.65 | K177: 6.52
A178: 172 | C178: SF5 | D178: PL6*30 | E178: 255 | F178: Q355B | G178: 390 | H178: 0.4 | I178: 140.5 | J178: 0.02 | K178: 7.3
A179: 173 | C179: SF6 | D179: PL6*30 | E179: 290 | F179: Q355B | G179: 130 | H179: 0.4 | I179: 53.3 | J179: 0.02 | K179: 2.76
A180: 174 | C180: SF7 | D180: PL6*30 | E180: 238 | F180: Q355B | G180: 72 | H180: 0.3 | I180: 24.2 | J180: 0.02 | K180: 1.26
A181: 175 | C181: SF8 | D181: PL6*30 | E181: 270 | F181: Q355B | G181: 168 | H181: 0.4 | I181: 64.1 | J181: 0.02 | K181: 3.33
A182: 176 | C182: SF9 | D182: PL16*90 | E182: 665 | F182: Q355B | G182: 136 | H182: 7.5 | I182: 1022.3 | J182: 0.14 | K182: 19.56
A183: 177 | C183: SF10 | D183: PL6*30 | E183: 305 | F183: Q355B | G183: 96 | H183: 0.4 | I183: 41.4 | J183: 0.02 | K183: 2.14
A184: 178 | C184: SF11 | D184: PL6*30 | E184: 220 | F184: Q355B | G184: 312 | H184: 0.3 | I184: 97 | J184: 0.02 | K184: 5.05
A185: 179 | C185: SF12 | D185: PL6*30 | E185: 320 | F185: Q355B | G185: 242 | H185: 0.5 | I185: 109.4 | J185: 0.02 | K185: 5.66
A186: 180 | C186: SF13 | D186: PL6*30 | E186: 390 | F186: Q355B | G186: 128 | H186: 0.6 | I186: 70.5 | J186: 0.03 | K186: 3.64
... A198: 192 | C198: SF25 | D198: PL6*30 | E198: 200 | F198: Q355B | G198: 2 | H198: 0.3 | I198: 0.6 | J198: 0.01 | K198: 0.03
A199: 193 | C199: TB1 | D199: PL5*950 | E199: 420 | F199: 花纹板 | G199: 110 | H199: 15.7 | I199: 1722.7 | J199: 0.81 | K199: 89.29 | L199: 踏步
A200: 194 | C200: TB2 | D200: PL5*950 | E200: 415 | F200: 花纹板 | G200: 136 | H200: 15.5 | I200: 2104.5 | J200: 0.8 | K200: 109.09
A201: 195 | C201: TB3 | D201: PL5*950 | E201: 385 | F201: 花纹板 | G201: 2 | H201: 14.4 | I201: 28.7 | J201: 0.74 | K201: 1.49
A202: 196 | C202: TB4 | D202: PL5*950 | E202: 405 | F202: 花纹板 | G202: 8 | H202: 15.1 | I202: 120.8 | J202: 0.78 | K202: 6.26
A203: 197 | C203: TB5 | D203: PL5*950 | E203: 405 | F203: 花纹板 | G203: 2 | H203: 15.1 | I203: 30.2 | J203: 0.78 | K203: 1.57
A204: 198 | C204: TB6 | D204: PL5*950 | E204: 390 | F204: 花纹板 | G204: 96 | H204: 14.5 | I204: 1396 | J204: 0.75 | K204: 72.42
A205: 199 | C205: TB7 | D205: PL5*950 | E205: 370 | F205: 花纹板 | G205: 3 | H205: 13.8 | I205: 41.4 | J205: 0.72 | K205: 2.15
A206: 200 | C206: TB8 | D206: PL5*950 | E206: 377.9 | F206: 花纹板 | G206: 9 | H206: 14.1 | I206: 126.8 | J206: 0.73 | K206: 6.58
...

Sheet 组立清单
A1: CSP卓越维保有限公司
B2: =清单封面!E18 -> 组立清单 | F2: =清单封面!F18 -> (仅型钢翼、腹板)
A4: =清单封面!B7 -> 工 程 名 称： | C4: =清单封面!C7 -> 第三选矿区C栋宿舍
A5: =清单封面!B8 -> 工 程 编 号： | C5: =清单封面!I18 -> HA24575
A6: 序号 | C6: 零件编号 | D6: 规格mm | E6: 长度mm | F6: 材质 | G6: 数量 | H6: 单重Kg | I6: 总重Kg | J6: 备注
A7: 1 | C7: H1 | D7: HI502-16-25*465 | E7: 10025 | F7: Q355B | G7: 55 | H7: 2398.8191 | I7: 131935.05
A8: 2 | C8: H2 | D8: HI502-16-25*465 | E8: 11325 | F8: Q355B | G8: 12 | H8: 2709.8879 | I8: 32518.655
A9: 3 | C9: H3 | D9: HI502-16-25*465 | E9: 17875 | F9: Q355B | G9: 12 | H9: 4277.1961 | I9: 51326.354
A10: 4 | C10: H4 | D10: HI600-12-20*200 | E10: 9385 | F10: Q355B | G10: 2 | H10: 1078.4895 | I10: 2156.979
A11: 5 | C11: H5 | D11: HI600-12-20*200 | E11: 9071 | F11: Q355B | G11: 1 | H11: 1048.1722 | I11: 1048.1722
A12: 6 | C12: H6 | D12: HI600-12-20*200 | E12: 9545 | F12: Q355B | G12: 21 | H12: 1102.9438 | I12: 23161.821
A13: 7 | C13: H7 | D13: HI600-12-20*200 | E13: 9079 | F13: Q355B | G13: 2 | H13: 1049.0966 | I13: 2098.1932
A14: 8 | C14: H7/8 | D14: HI600-12-20*200 | E14: 9754 | F14: Q355B | G14: 1 | H14: 1127.0942 | I14: 1127.0942
A15: 9 | C15: H9 | D15: HI600-12-20*200 | E15: 6018 | F15: Q355B | G15: 1 | H15: 695.39194 | I15: 695.39194
A16: 10 | C16: H9A | D16: HI600-12-20*200 | E16: 4011 | F16: Q355B | G16: 1 | H16: 463.47907 | I16: 463.47907
A17: 11 | C17: H10 | D17: HI600-12-20*200 | E17: 8998 | F17: Q355B | G17: 19 | H17: 1039.7369 | I17: 19755.001
A18: 12 | C18: H11 | D18: HI600-12-20*200 | E18: 11197 | F18: Q355B | G18: 1 | H18: 1293.8357 | I18: 1293.8357
... A103: 97 | C103: H114/115 | D103: HI300-6-10*200 | E103: 8559 | F103: Q355B | G103: 2 | H103: 381.62869 | I103: 763.25738
F104: 合计： | G104: =SUM(G7:G103) -> 606 | I104: =SUM(I7:I103) -> 642007.23 | K104: 此行严禁删除！

Sheet 排板清单
A1: CSP卓越维保有限公司
A2: =清单封面!E19 -> 排版清单 | F2: =清单封面!F19 -> (仅型钢翼、腹板，未加余量)
A4: =清单封面!B7 -> 工 程 名 称： | C4: =清单封面!C7 -> 第三选矿区C栋宿舍
A5: =清单封面!B8 -> 工 程 编 号： | C5: =清单封面!I19 -> HA24575
A6: 序号 | C6: 规格mm | D6: 材质 | E6: 宽度mm | F6: 长度mm | G6: 数量 | H6: 总重Kg | I6: 备注
A7: 1 | C7: 6 | D7: Q355B | E7: 1500 | F7: 6194 | G7: 1 | H7: 437.6061
A8: 2 | C8: 6 | D8: Q355B | E8: 1500 | F8: 7627 | G8: 1 | H8: 538.84755
A9: 3 | C9: 6 | D9: Q355B | E9: 1500 | F9: 11349 | G9: 1 | H9: 801.80685
A10: 4 | C10: 6汇总 | G10: =SUM(G7:G9) -> 3 | H10: =SUM(H7:H9) -> 1778.2605
A11: 5
A12: 6 | C12: 8 | D12: Q355B | E12: 1500 | F12: 4122 | G12: 1 | H12: 388.2924
A13: 7 | C13: 8 | D13: Q355B | E13: 1500 | F13: 5497 | G13: 1 | H13: 517.8174
A14: 8 | C14: 8 | D14: Q355B | E14: 1500 | F14: 5763 | G14: 1 | H14: 542.8746
A15: 9 | C15: 8 | D15: Q355B | E15: 1500 | F15: 6196 | G15: 1 | H15: 583.6632
A16: 10 | C16: 8 | D16: Q355B | E16: 1500 | F16: 6400 | G16: 4 | H16: 2411.52
A17: 11 | C17: 8 | D17: Q355B | E17: 1500 | F17: 6517 | G17: 1 | H17: 613.9014
A18: 12 | C18: 8 | D18: Q355B | E18: 1500 | F18: 7403 | G18: 1 | H18: 697.3626
A19: 13 | C19: 8 | D19: Q355B | E19: 1500 | F19: 7607 | G19: 1 | H19: 716.5794
A20: 14 | C20: 8 | D20: Q355B | E20: 1500 | F20: 7731 | G20: 1 | H20: 728.2602
A21: 15 | C21: 8 | D21: Q355B | E21: 1500 | F21: 8046 | G21: 12 | H21: 9095.1984
A22: 16 | C22: 8 | D22: Q355B | E22: 1500 | F22: 8547 | G22: 1 | H22: 805.1274
A23: 17 | C23: 8 | D23: Q355B | E23: 1500 | F23: 9045 | G23: 1 | H23: 852.039
... A30: 24 | C30: 8 | D30: Q355B | E30: 1500 | F30: 11529 | G30: 1 | H30: 1086.0318
A31: 25 | C31: 8汇总 | G31: =SUM(G12:G30) -> 44 | H31: =SUM(H12:H30) -> 36645.307
A32: 26
A33: 27 | C33: 10 | D33: Q355B | E33: 1500 | F33: 6196 | G33: 2 | H33: 1459.158
A34: 28 | C34: 10 | D34: Q355B | E34: 1500 | F34: 6258 | G34: 1 | H34: 736.8795
A35: 29 | C35: 10 | D35: Q355B | E35: 1500 | F35: 6400 | G35: 5 | H35: 3768
A36: 30 | C36: 10 | D36: Q355B | E36: 1500 | F36: 6461 | G36: 2 | H36: 1521.5655
A37: 31 | C37: 10 | D37: Q355B | E37: 1500 | F37: 7403 | G37: 1 | H37: 871.70325
A38: 32 | C38: 10 | D38: Q355B | E38: 1500 | F38: 7627 | G38: 1 | H38: 898.07925
A39: 33 | C39: 10 | D39: Q355B | E39: 1500 | F39: 7731 | G39: 1 | H39: 910.32525
A40: 34 | C40: 10 | D40: Q355B | E40: 1500 | F40: 8046 | G40: 17 | H40: 16106.081
A41: 35 | C41: 10 | D41: Q355B | E41: 1500 | F41: 8389 | G41: 1 | H41: 987.80475
A42: 36 | C42: 10 | D42: Q355B | E42: 1500 | F42: 8529 | G42: 1 | H42: 1004.2898
A43: 37 | C43: 10 | D43: Q355B | E43: 1500 | F43: 8547 | G43: 1 | H43: 1006.4093
A44: 38 | C44: 10 | D44: Q355B | E44: 1500 | F44: 8559 | G44: 1 | H44: 1007.8223
... A52: 46 | C52: 10 | D52: Q355B | E52: 1500 | F52: 20485 | G52: 2 | H52: 4824.2175
A53: 47 | C53: 10汇总 | G53: =SUM(G33:G52) -> 60 | H53: =SUM(H33:H52) -> 66634.961
A54: 48
...
